<?xml version="1.0"?>

<robot name="robot">

  <!-- Color of materials -->
  <material name="yellow">
    <color rgba="1 1 0 1"/>
  </material>
  <material name="blue">
    <color rgba="0 0 1 1"/>
  </material>
  <material name="red">
    <color rgba="1 0 0 1"/>
  </material>
  <material name="white">
    <color rgba="1 1 1 1"/>
  </material>
  <material name="grey">
    <color rgba="0.4 0.4 0.4 1"/>
  </material>
  <material name="green">
    <color rgba="0 1 0 1"/>
  </material>

  <!-- The base is declared -->

  <link name="base">
    <visual>
      <geometry>
        <mesh filename="package://simulation/meshes/Base.stl" scale="0.001 0.001 0.001"/>
      </geometry>
      <origin rpy="0 0 0" xyz="0 0 0.228"/>
      <material name="white" />
    </visual>
    <collision>
      <origin rpy="0 0 0" xyz="0 0 0.228"/>
      <geometry>
        <box size="0.145 0.145 0.05"/>
      </geometry>
    </collision>
    <inertial>
      <origin rpy="0 0 0" xyz="0 0 0.228"/>
      <mass value="1" />
      <inertia ixx="0.000588125" ixy="0.0" ixz="0.0" iyy="0.00105125" iyz="0.0" izz="0.000588125" />
    </inertial>
  </link>
  <gazebo reference="base">
    <material>Gazebo/White</material>
  </gazebo>

  <!-- Base fixed joints are assigned -->

  <joint name="base_leg1" type="fixed">
    <parent link="base"/>
    <child link="leg1_c1"/>
    <origin xyz="0.093 -0.093 0.225"/>
    <axis xyz="0 0 1" />
    <limit effort="300" velocity="2" lower="-1.57" upper="1.57"/>
  </joint>

  <joint name="base_leg2" type="fixed">
    <parent link="base"/>
    <child link="leg2_c1"/>
    <origin xyz="0.093 0.093 0.225"/>
    <axis xyz="0 0 1" />
    <limit effort="300" velocity="2" lower="-1.57" upper="1.57"/>
  </joint>

  <joint name="base_leg3" type="fixed">
    <parent link="base"/>
    <child link="leg3_c1"/>
    <origin xyz="-0.093 -0.093 0.225"/>
    <axis xyz="0 0 1" />
    <limit effort="300" velocity="2" lower="-1.57" upper="1.57"/>
  </joint>

  <joint name="base_leg4" type="fixed">
    <parent link="base"/>
    <child link="leg4_c1"/>
    <origin xyz="-0.093 0.093 0.225"/>
    <axis xyz="0 0 1" />
    <limit effort="300" velocity="2" lower="-1.57" upper="1.57"/>
  </joint>

  <!-- Base cylinders are created -->

  <link name="leg1_c1">
    <visual>
      <geometry>
        <mesh filename="package://simulation/meshes/Motor1.stl" scale="0.001 0.001 0.001"/>
      </geometry>
      <origin xyz="0 0 0" rpy="0 0 -0.785398"/>
      <material name="grey"/>
    </visual>
    <collision>
      <origin xyz="0 0 0" rpy="0 0 -0.785398"/>
      <geometry>
        <cylinder length="0.05" radius="0.02"/>
      </geometry>
    </collision>
    <inertial>
      <origin rpy="0 0 -0.785398" xyz="-0.008 0.008 0"/>
      <mass value="1" />
      <inertia ixx="2.0289e-4" ixy="0" ixz="0" iyy="2.0048e-4" iyz="0" izz="1.8752e-4" />
    </inertial>
  </link>
  <gazebo reference="leg1_c1">
    <material>Gazebo/Grey</material>
  </gazebo>

  <link name="leg2_c1">
    <visual>
      <geometry>
        <mesh filename="package://simulation/meshes/Motor1.stl" scale="0.001 0.001 0.001"/>
      </geometry>
      <origin xyz="0 0 0" rpy="0 0 0.785398"/>
      <material name="grey"/>
    </visual>
    <collision>
      <origin xyz="0 0 0" rpy="0 0 0.785398"/>
      <geometry>
        <cylinder length="0.05" radius="0.02"/>
      </geometry>
    </collision>
    <inertial>
      <origin rpy="0 0 0.785398" xyz="-0.008 -0.008 0"/>
      <mass value="0.061" />
      <inertia ixx="2.0289e-4" ixy="0" ixz="0" iyy="2.0048e-4" iyz="0" izz="1.8752e-4" />
    </inertial>
  </link>
  <gazebo reference="leg2_c1">
    <material>Gazebo/Grey</material>
  </gazebo>>

  <link name="leg3_c1">
    <visual>
      <geometry>
        <mesh filename="package://simulation/meshes/Motor1.stl" scale="0.001 0.001 0.001"/>
      </geometry>
      <origin xyz="0 0 0" rpy="0 0 -2.356102"/>
      <material name="grey"/>
    </visual>
    <collision>
      <origin xyz="0 0 0" rpy="0 0 -2.356102"/>
      <geometry>
        <cylinder length="0.05" radius="0.02"/>
      </geometry>
    </collision>
    <inertial>
      <origin rpy="0 0 0" xyz="0 0 0"/>
      <mass value="0.061" />
      <inertia ixx="2.0289e-5" ixy="0" ixz="0" iyy="2.0048e-5" iyz="0" izz="1.8752e-5" />
    </inertial>
  </link>
  <gazebo reference="leg3_c1">
    <material>Gazebo/Grey</material>
  </gazebo>

  <link name="leg4_c1">
    <visual>
      <geometry>
        <mesh filename="package://simulation/meshes/Motor1.stl" scale="0.001 0.001 0.001"/>
      </geometry>
      <origin xyz="0 0 0" rpy="0 0 2.356102"/>
      <material name="grey"/>
    </visual>
    <collision>
      <origin xyz="0 0 0" rpy="0 0 2.356102"/>
      <geometry>
        <cylinder length="0.05" radius="0.02"/>
      </geometry>
    </collision>
    <inertial>
      <origin rpy="0 0 0" xyz="0 0 0"/>
      <mass value="0.061" />
      <inertia ixx="2.0289e-5" ixy="0" ixz="0" iyy="2.0048e-5" iyz="0" izz="1.8752e-5" />
    </inertial>
  </link>
  <gazebo reference="leg4_c1">
    <material>Gazebo/Grey</material>
  </gazebo>

  <!-- Motor 1 are assigned -->

  <joint name="leg1_motor1" type="revolute">
    <parent link="leg1_c1"/>
    <child link="leg1_bar1"/>
    <origin xyz="0 0 0" rpy="0 0 -2.35619"/>
    <axis xyz="0 0 1" />
    <limit effort="300" velocity="2" lower="0" upper="3.1416"/>
    <dynamics damping="15" friction="3"/>
  </joint>

  <joint name="leg2_motor1" type="revolute">
    <parent link="leg2_c1"/>
    <child link="leg2_bar1"/>
    <origin xyz="0 0 0" rpy="0 0 -0.785398"/>
    <axis xyz="0 0 1" />
    <limit effort="300" velocity="2" lower="0" upper="3.1416"/>
    <dynamics damping="15" friction="3"/>
  </joint>

  <joint name="leg3_motor1" type="revolute">
    <parent link="leg3_c1"/>
    <child link="leg3_bar1"/>
    <origin xyz="0 0 0" rpy="0 0 2.35619"/>
    <axis xyz="0 0 1" />
    <limit effort="300" velocity="2" lower="0" upper="3.1416"/>
    <dynamics damping="15" friction="3"/>
  </joint>

  <joint name="leg4_motor1" type="revolute">
    <parent link="leg4_c1"/>
    <child link="leg4_bar1"/>
    <origin xyz="0 0 0" rpy="0 0 0.785398"/>
    <axis xyz="0 0 1" />
    <limit effort="300" velocity="2" lower="0" upper="3.1416"/>
    <dynamics damping="15" friction="3"/>
  </joint>

  <!-- First bars are assigned -->

  <link name="leg1_bar1">
    <visual>
      <geometry>
        <mesh filename="package://simulation/meshes/Vara1.stl" scale="0.001 0.001 0.001"/>
      </geometry>
      <origin rpy="0 1.57 0" xyz="0.0275 0 0"/>
      <material name="white" />
    </visual>
    <collision>
      <origin rpy="0 1.57 0" xyz="0.0275 0 0"/>
      <geometry>
        <cylinder length="0.055" radius="0.01"/>
      </geometry>
    </collision>
    <inertial>
      <origin rpy="0 0 0" xyz="0 0 0"/>
      <mass value="0.027" />
      <inertia ixx="0.000644294" ixy="0" ixz="0" iyy="0.000446702" iyz="0" izz="0.001002314" />
    </inertial>
  </link>
  <gazebo reference="leg1_bar1">
    <material>Gazebo/White</material>
  </gazebo>

  <link name="leg2_bar1">
    <visual>
      <geometry>
        <mesh filename="package://simulation/meshes/Vara1.stl" scale="0.001 0.001 0.001"/>
      </geometry>
      <origin rpy="0 1.57 0" xyz="0.0275 0 0"/>
      <material name="white" />
    </visual>
    <collision>
      <origin rpy="0 1.57 0" xyz="0.0275 0 0"/>
      <geometry>
        <cylinder length="0.055" radius="0.01"/>
      </geometry>
    </collision>
    <inertial>
      <origin rpy="0 0 0" xyz="0 0 0"/>
      <mass value="0.027" />
      <inertia ixx="0.000644294" ixy="0" ixz="0" iyy="0.000446702" iyz="0" izz="0.001002314" />
    </inertial>
  </link>
  <gazebo reference="leg2_bar1">
    <material>Gazebo/White</material>
  </gazebo>

  <link name="leg3_bar1">
    <visual>
      <geometry>
        <mesh filename="package://simulation/meshes/Vara1.stl" scale="0.001 0.001 0.001"/>
      </geometry>
      <origin rpy="0 1.57 0" xyz="0.0275 0 0"/>
      <material name="white" />
    </visual>
    <collision>
      <origin rpy="0 1.57 0" xyz="0.0275 0 0"/>
      <geometry>
        <cylinder length="0.055" radius="0.01"/>
      </geometry>
    </collision>
    <inertial>
      <origin rpy="0 0 0" xyz="0 0 0"/>
      <mass value="0.027" />
      <inertia ixx="0.000644294" ixy="0" ixz="0" iyy="0.000446702" iyz="0" izz="0.001002314" />
    </inertial>
  </link>
  <gazebo reference="leg3_bar1">
    <material>Gazebo/White</material>
  </gazebo>

  <link name="leg4_bar1">
    <visual>
      <geometry>
        <mesh filename="package://simulation/meshes/Vara1.stl" scale="0.001 0.001 0.001"/>
      </geometry>
      <origin rpy="0 1.57 0" xyz="0.0275 0 0"/>
      <material name="white" />
    </visual>
    <collision>
      <origin rpy="0 1.57 0" xyz="0.0275 0 0"/>
      <geometry>
        <cylinder length="0.055" radius="0.01"/>
      </geometry>
    </collision>
    <inertial>
      <origin rpy="0 0 0" xyz="0 0 0"/>
      <mass value="0.027" />
      <inertia ixx="0.000644294" ixy="0" ixz="0" iyy="0.000446702" iyz="0" izz="0.001002314" />
    </inertial>
  </link>
  <gazebo reference="leg4_bar1">
    <material>Gazebo/White</material>
  </gazebo>

  <!-- First bars fixed joints are assigned -->

  <joint name="leg1_bar1_fix" type="fixed">
    <parent link="leg1_bar1"/>
    <child link="leg1_c2"/>
    <origin xyz="0.055 0 0"/>
    <axis xyz="0 0 1" />
    <limit effort="300" velocity="2" lower="-1.57" upper="1.57"/>
  </joint>

  <joint name="leg2_bar1_fix" type="fixed">
    <parent link="leg2_bar1"/>
    <child link="leg2_c2"/>
    <origin xyz="0.055 0 0"/>
    <axis xyz="0 0 1" />
    <limit effort="300" velocity="2" lower="-1.57" upper="1.57"/>
  </joint>

  <joint name="leg3_bar1_fix" type="fixed">
    <parent link="leg3_bar1"/>
    <child link="leg3_c2"/>
    <origin xyz="0.055 0 0"/>
    <axis xyz="0 0 1" />
    <limit effort="300" velocity="2" lower="-1.57" upper="1.57"/>
  </joint>

  <joint name="leg4_bar1_fix" type="fixed">
    <parent link="leg4_bar1"/>
    <child link="leg4_c2"/>
    <origin xyz="0.055 0 0"/>
    <axis xyz="0 0 1" />
    <limit effort="300" velocity="2" lower="-1.57" upper="1.57"/>
  </joint>


  <!-- Second motor cylinders are created -->

  <link name="leg1_c2">
    <visual>
      <geometry>
        <mesh filename="package://simulation/meshes/Motor2.stl" scale="0.001 0.001 0.001"/>
      </geometry>
      <origin rpy="1.57 0 0" xyz="0 0 0"/>
      <material name="grey" />
    </visual>
    <collision>
      <origin rpy="1.57 0 0" xyz="0 0 0"/>
      <geometry>
        <cylinder length="0.05" radius="0.02"/>
      </geometry>
    </collision>
    <inertial>
      <origin rpy="0 0 0" xyz="0 0 0"/>
      <mass value="0.061" />
      <inertia ixx="2.0289e-5" ixy="0" ixz="0" iyy="2.0048e-5" iyz="0" izz="1.8752e-5" />
    </inertial>
  </link>
  <gazebo reference="leg1_c2">
    <material>Gazebo/Grey</material>
  </gazebo>

  <link name="leg2_c2">
    <visual>
      <geometry>
        <mesh filename="package://simulation/meshes/Motor2.stl" scale="0.001 0.001 0.001"/>
      </geometry>
      <origin rpy="1.57 0 0" xyz="0 0 0"/>
      <material name="grey" />
    </visual>
    <collision>
      <origin rpy="1.57 0 0" xyz="0 0 0"/>
      <geometry>
        <cylinder length="0.05" radius="0.02"/>
      </geometry>
    </collision>
    <inertial>
      <origin rpy="0 0 0" xyz="0 0 0"/>
      <mass value="0.061" />
      <inertia ixx="2.0289e-5" ixy="0" ixz="0" iyy="2.0048e-5" iyz="0" izz="1.8752e-5" />
    </inertial>
  </link>
  <gazebo reference="leg2_c2">
    <material>Gazebo/Grey</material>
  </gazebo>

  <link name="leg3_c2">
    <visual>
      <geometry>
        <mesh filename="package://simulation/meshes/Motor2.stl" scale="0.001 0.001 0.001"/>
      </geometry>
      <origin rpy="1.57 0 0" xyz="0 0 0"/>
      <material name="grey" />
    </visual>
    <collision>
      <origin rpy="1.57 0 0" xyz="0 0 0"/>
      <geometry>
        <cylinder length="0.05" radius="0.02"/>
      </geometry>
    </collision>
    <inertial>
      <origin rpy="0 0 0" xyz="0 0 0"/>
      <mass value="0.061" />
      <inertia ixx="2.0289e-5" ixy="0" ixz="0" iyy="2.0048e-5" iyz="0" izz="1.8752e-5" />
    </inertial>
  </link>
  <gazebo reference="leg3_c2">
    <material>Gazebo/Grey</material>
  </gazebo>

  <link name="leg4_c2">
    <visual>
      <geometry>
        <mesh filename="package://simulation/meshes/Motor2.stl" scale="0.001 0.001 0.001"/>
      </geometry>
      <origin rpy="1.57 0 0" xyz="0 0 0"/>
      <material name="grey" />
    </visual>
    <collision>
      <origin rpy="1.57 0 0" xyz="0 0 0"/>
      <geometry>
        <cylinder length="0.05" radius="0.02"/>
      </geometry>
    </collision>
    <inertial>
      <origin rpy="0 0 0" xyz="0 0 0"/>
      <mass value="0.061" />
      <inertia ixx="2.0289e-5" ixy="0" ixz="0" iyy="2.0048e-5" iyz="0" izz="1.8752e-5" />
    </inertial>
  </link>
  <gazebo reference="leg4_c2">
    <material>Gazebo/Grey</material>
  </gazebo>

  <!-- Motor 2 are assigned -->

  <joint name="leg1_motor2" type="revolute">
    <parent link="leg1_c2"/>
    <child link="leg1_bar2"/>
    <origin xyz="0 0 0" rpy="0 0 0"/>
    <axis xyz="0 -1 0" />
    <limit effort="300" velocity="2" lower="0" upper="3.1416"/>
    <dynamics damping="15" friction="3"/>
  </joint>

  <joint name="leg2_motor2" type="revolute">
    <parent link="leg2_c2"/>
    <child link="leg2_bar2"/>
    <origin xyz="0 0 0" rpy="0 0 0"/>
    <axis xyz="0 -1 0" />
    <limit effort="300" velocity="2" lower="0" upper="3.1416"/>
    <dynamics damping="15" friction="3"/>
  </joint>

  <joint name="leg3_motor2" type="revolute">
    <parent link="leg3_c2"/>
    <child link="leg3_bar2"/>
    <origin xyz="0 0 0" rpy="0 0 0"/>
    <axis xyz="0 -1 0" />
    <limit effort="300" velocity="2" lower="0" upper="3.1416"/>
    <dynamics damping="15" friction="3"/>
  </joint>

  <joint name="leg4_motor2" type="revolute">
    <parent link="leg4_c2"/>
    <child link="leg4_bar2"/>
    <origin xyz="0 0 0" rpy="0 0 0"/>
    <axis xyz="0 -1 0" />
    <limit effort="300" velocity="2" lower="0" upper="3.1416"/>
    <dynamics damping="15" friction="3"/>
  </joint>

  <!-- Second bars are assigned -->

  <link name="leg1_bar2">
    <visual>
      <geometry>
        <mesh filename="package://simulation/meshes/Vara2.stl" scale="0.001 0.001 0.001"/>
      </geometry>
      <origin rpy="0 0 0" xyz="0 0 -0.0375"/>
      <material name="white" />
    </visual>
    <collision>
      <origin rpy="0 0 0" xyz="0 0 -0.0375"/>
      <geometry>
        <cylinder length="0.075" radius="0.01"/>
      </geometry>
    </collision>
    <inertial>
      <origin rpy="0 0 0" xyz="0 0 0"/>
      <mass value="0.0214" />
      <inertia ixx="0.000324045" ixy="0" ixz="0" iyy="0.000180021" iyz="0" izz="0.000355567" />
    </inertial>
  </link>
  <gazebo reference="leg1_bar2">
    <material>Gazebo/White</material>
  </gazebo>

  <link name="leg2_bar2">
    <visual>
      <geometry>
        <mesh filename="package://simulation/meshes/Vara2.stl" scale="0.001 0.001 0.001"/>
      </geometry>
      <origin rpy="0 0 0" xyz="0 0 -0.0375"/>
      <material name="white" />
    </visual>
    <collision>
      <origin rpy="0 0 0" xyz="0 0 -0.0375"/>
      <geometry>
        <cylinder length="0.075" radius="0.01"/>
      </geometry>
    </collision>
    <inertial>
      <origin rpy="0 0 0" xyz="0 0 0"/>
      <mass value="0.0214" />
      <inertia ixx="0.000324045" ixy="0" ixz="0" iyy="0.000180021" iyz="0" izz="0.000355567" />
    </inertial>
  </link>
  <gazebo reference="leg2_bar2">
    <material>Gazebo/White</material>
  </gazebo>

  <link name="leg3_bar2">
    <visual>
      <geometry>
        <mesh filename="package://simulation/meshes/Vara2.stl" scale="0.001 0.001 0.001"/>
      </geometry>
      <origin rpy="0 0 0" xyz="0 0 -0.0375"/>
      <material name="white" />
    </visual>
    <collision>
      <origin rpy="0 0 0" xyz="0 0 -0.0375"/>
      <geometry>
        <cylinder length="0.075" radius="0.01"/>
      </geometry>
    </collision>
    <inertial>
      <origin rpy="0 0 0" xyz="0 0 0"/>
      <mass value="0.0214" />
      <inertia ixx="0.000324045" ixy="0" ixz="0" iyy="0.000180021" iyz="0" izz="0.000355567" />
    </inertial>
  </link>
  <gazebo reference="leg3_bar2">
    <material>Gazebo/White</material>
  </gazebo>

  <link name="leg4_bar2">
    <visual>
      <geometry>
        <mesh filename="package://simulation/meshes/Vara2.stl" scale="0.001 0.001 0.001"/>
      </geometry>
      <origin rpy="0 0 0" xyz="0 0 -0.0375"/>
      <material name="white" />
    </visual>
    <collision>
      <origin rpy="0 0 0" xyz="0 0 -0.0375"/>
      <geometry>
        <cylinder length="0.075" radius="0.01"/>
      </geometry>
    </collision>
    <inertial>
      <origin rpy="0 0 0" xyz="0 0 0"/>
      <mass value="0.0214" />
      <inertia ixx="0.000324045" ixy="0" ixz="0" iyy="0.000180021" iyz="0" izz="0.000355567" />
    </inertial>
  </link>
  <gazebo reference="leg4_bar2">
    <material>Gazebo/White</material>
  </gazebo>

  <!-- Second bars fixed joints are assigned -->

  <joint name="leg1_bar2_fix" type="fixed">
    <parent link="leg1_bar2"/>
    <child link="leg1_c3"/>
    <origin xyz="0 0 -0.075"/>
    <axis xyz="0 0 1" />
    <limit effort="300" velocity="2" lower="-1.57" upper="1.57"/>
  </joint>

  <joint name="leg2_bar2_fix" type="fixed">
    <parent link="leg2_bar2"/>
    <child link="leg2_c3"/>
    <origin xyz="0 0 -0.075"/>
    <axis xyz="0 0 1" />
    <limit effort="300" velocity="2" lower="-1.57" upper="1.57"/>
  </joint>

  <joint name="leg3_bar2_fix" type="fixed">
    <parent link="leg3_bar2"/>
    <child link="leg3_c3"/>
    <origin xyz="0 0 -0.075"/>
    <axis xyz="0 0 1" />
    <limit effort="300" velocity="2" lower="-1.57" upper="1.57"/>
  </joint>

  <joint name="leg4_bar2_fix" type="fixed">
    <parent link="leg4_bar2"/>
    <child link="leg4_c3"/>
    <origin xyz="0 0 -0.075"/>
    <axis xyz="0 0 1" />
    <limit effort="300" velocity="2" lower="-1.57" upper="1.57"/>
  </joint>

  <!-- Motor 3 cylinders are assigned -->

  <link name="leg1_c3">
    <visual>
      <geometry>
        <mesh filename="package://simulation/meshes/Motor3.stl" scale="0.001 0.001 0.001"/>
      </geometry>
      <origin rpy="1.57 0 0" xyz="0 0 0"/>
      <material name="grey" />
    </visual>
    <collision>
      <origin rpy="1.57 0 0" xyz="0 0 0"/>
      <geometry>
        <cylinder length="0.05" radius="0.02"/>
      </geometry>
    </collision>
    <inertial>
      <origin rpy="0 0 0" xyz="0 0 0"/>
      <mass value="0.061" />
      <inertia ixx="2.0289e-5" ixy="0" ixz="0" iyy="2.0048e-5" iyz="0" izz="1.8752e-5" />
    </inertial>
  </link>
  <gazebo reference="leg1_c3">
    <material>Gazebo/Grey</material>
  </gazebo>

  <link name="leg2_c3">
    <visual>
      <geometry>
        <mesh filename="package://simulation/meshes/Motor3.stl" scale="0.001 0.001 0.001"/>
      </geometry>
      <origin rpy="1.57 0 0" xyz="0 0 0"/>
      <material name="grey" />
    </visual>
    <collision>
      <origin rpy="1.57 0 0" xyz="0 0 0"/>
      <geometry>
        <cylinder length="0.05" radius="0.02"/>
      </geometry>
    </collision>
    <inertial>
      <origin rpy="0 0 0" xyz="0 0 0"/>
      <mass value="0.061" />
      <inertia ixx="2.0289e-5" ixy="0" ixz="0" iyy="2.0048e-5" iyz="0" izz="1.8752e-5" />
    </inertial>
  </link>
  <gazebo reference="leg2_c3">
    <material>Gazebo/Grey</material>
  </gazebo>

  <link name="leg3_c3">
    <visual>
      <geometry>
        <mesh filename="package://simulation/meshes/Motor3.stl" scale="0.001 0.001 0.001"/>
      </geometry>
      <origin rpy="1.57 0 0" xyz="0 0 0"/>
      <material name="grey" />
    </visual>
    <collision>
      <origin rpy="1.57 0 0" xyz="0 0 0"/>
      <geometry>
        <cylinder length="0.05" radius="0.02"/>
      </geometry>
    </collision>
    <inertial>
      <origin rpy="0 0 0" xyz="0 0 0"/>
      <mass value="0.061" />
      <inertia ixx="2.0289e-5" ixy="0" ixz="0" iyy="2.0048e-5" iyz="0" izz="1.8752e-5" />
    </inertial>
  </link>
  <gazebo reference="leg3_c3">
    <material>Gazebo/Grey</material>
  </gazebo>

  <link name="leg4_c3">
    <visual>
      <geometry>
        <mesh filename="package://simulation/meshes/Motor3.stl" scale="0.001 0.001 0.001"/>
      </geometry>
      <origin rpy="1.57 0 0" xyz="0 0 0"/>
      <material name="grey" />
    </visual>
    <collision>
      <origin rpy="1.57 0 0" xyz="0 0 0"/>
      <geometry>
        <cylinder length="0.05" radius="0.02"/>
      </geometry>
    </collision>
    <inertial>
      <origin rpy="0 0 0" xyz="0 0 0"/>
      <mass value="0.061" />
      <inertia ixx="2.0289e-5" ixy="0" ixz="0" iyy="2.0048e-5" iyz="0" izz="1.8752e-5" />
    </inertial>
  </link>
  <gazebo reference="leg4_c3">
    <material>Gazebo/Grey</material>
  </gazebo>

  <!-- Motor 3 are assigned -->

  <joint name="leg1_motor3" type="revolute">
    <parent link="leg1_c3"/>
    <child link="leg1_bar3"/>
    <origin xyz="0 0 0"/>
    <axis xyz="0 1 0" />
    <limit effort="300" velocity="2" lower="0" upper="3.1416"/>
    <dynamics damping="15" friction="3"/>
    <sensor name="force_torque" type="force_torque">
      <update_rate>30</update_rate>
    </sensor>
  </joint>

  <joint name="leg2_motor3" type="revolute">
    <parent link="leg2_c3"/>
    <child link="leg2_bar3"/>
    <origin xyz="0 0 0"/>
    <axis xyz="0 1 0" />
    <limit effort="300" velocity="2" lower="0" upper="3.1416"/>
    <dynamics damping="15" friction="3"/>
    <sensor name="force_torque" type="force_torque">
      <update_rate>30</update_rate>
    </sensor>
  </joint>

  <joint name="leg3_motor3" type="revolute">
    <parent link="leg3_c3"/>
    <child link="leg3_bar3"/>
    <origin xyz="0 0 0"/>
    <axis xyz="0 1 0" />
    <limit effort="300" velocity="2" lower="0" upper="3.1416"/>
    <dynamics damping="15" friction="3"/>
    <sensor name="force_torque" type="force_torque">
      <update_rate>30</update_rate>
    </sensor>
  </joint>

  <joint name="leg4_motor3" type="revolute">
    <parent link="leg4_c3"/>
    <child link="leg4_bar3"/>
    <origin xyz="0 0 0"/>
    <axis xyz="0 1 0" />
    <limit effort="300" velocity="2" lower="0" upper="3.1416"/>
    <dynamics damping="15" friction="3"/>
    <sensor name="force_torque" type="force_torque">
      <update_rate>30</update_rate>
    </sensor>
  </joint>

  <!-- Third bars are assigned -->

  <link name="leg1_bar3">
    <visual>
      <geometry>
        <mesh filename="package://simulation/meshes/Leg.stl" scale="0.001 0.001 0.001"/>
      </geometry>
      <origin rpy="0 0 0" xyz="0 0 0"/>
      <material name="white" />
    </visual>
    <collision>
      <origin rpy="0 0 0" xyz="0 0 -0.1"/>
      <geometry>
        <cylinder length="0.225" radius="0.023"/>
      </geometry>
    </collision>
    <inertial>
      <origin rpy="0 0 0" xyz="0 0 -0.095924"/>
      <mass value="0.1118" />
      <inertia ixx="0.001947133" ixy="0" ixz="0" iyy="0.001408573" iyz="0" izz="0.000804606" />
    </inertial>
  </link>
  <gazebo reference="leg1_bar3">
    <material>Gazebo/White</material>
  </gazebo>

  <link name="leg2_bar3">
    <visual>
      <geometry>
        <mesh filename="package://simulation/meshes/Leg.stl" scale="0.001 0.001 0.001"/>
      </geometry>
      <origin rpy="0 0 0" xyz="0 0 0"/>
      <material name="white" />
    </visual>
    <collision>
      <origin rpy="0 0 0" xyz="0 0 -0.1"/>
      <geometry>
        <cylinder length="0.225" radius="0.023"/>
      </geometry>
    </collision>
    <inertial>
      <origin rpy="0 0 0" xyz="0 0 -0.095924"/>
      <mass value="0.1118" />
      <inertia ixx="0.001947133" ixy="0" ixz="0" iyy="0.001408573" iyz="0" izz="0.000804606" />
    </inertial>
  </link>
  <gazebo reference="leg2_bar3">
    <material>Gazebo/White</material>
  </gazebo>

  <link name="leg3_bar3">
    <visual>
      <geometry>
        <mesh filename="package://simulation/meshes/Leg.stl" scale="0.001 0.001 0.001"/>
      </geometry>
      <origin rpy="0 0 0" xyz="0 0 0"/>
      <material name="white" />
    </visual>
    <collision>
      <origin rpy="0 0 0" xyz="0 0 -0.1"/>
      <geometry>
        <cylinder length="0.225" radius="0.023"/>
      </geometry>
    </collision>
    <inertial>
      <origin rpy="0 0 0" xyz="0 0 -0.095924"/>
      <mass value="0.1118" />
      <inertia ixx="0.001947133" ixy="0" ixz="0" iyy="0.001408573" iyz="0" izz="0.000804606" />
    </inertial>
  </link>
  <gazebo reference="leg3_bar3">
    <material>Gazebo/White</material>
  </gazebo>

  <link name="leg4_bar3">
    <visual>
      <geometry>
        <mesh filename="package://simulation/meshes/Leg.stl" scale="0.001 0.001 0.001"/>
      </geometry>
      <origin rpy="0 0 0" xyz="0 0 0"/>
      <material name="white" />
    </visual>
    <collision>
      <origin rpy="0 0 0" xyz="0 0 -0.1"/>
      <geometry>
        <cylinder length="0.225" radius="0.023"/>
      </geometry>
    </collision>
    <inertial>
      <origin rpy="0 0 0" xyz="0 0 -0.095924"/>
      <mass value="0.1118" />
      <inertia ixx="0.001947133" ixy="0" ixz="0" iyy="0.001408573" iyz="0" izz="0.000804606" />
    </inertial>
  </link>
  <gazebo reference="leg4_bar3">
    <material>Gazebo/White</material>
  </gazebo>

  <!-- Third bars fixes are assigned -->

  <joint name="leg1_bar3_fix" type="fixed">
    <parent link="leg1_bar3"/>
    <child link="leg1_end"/>
    <origin xyz="0 0 -0.216284"/>
    <axis xyz="0 0 1" />
    <limit effort="300" velocity="2" lower="-1.57" upper="1.57"/>
  </joint>

  <joint name="leg2_bar3_fix" type="fixed">
    <parent link="leg2_bar3"/>
    <child link="leg2_end"/>
    <origin xyz="0 0 -0.216284"/>
    <axis xyz="0 0 1" />
    <limit effort="300" velocity="2" lower="-1.57" upper="1.57"/>
  </joint>

  <joint name="leg3_bar3_fix" type="fixed">
    <parent link="leg3_bar3"/>
    <child link="leg3_end"/>
    <origin xyz="0 0 -0.216284"/>
    <axis xyz="0 0 1" />
    <limit effort="300" velocity="2" lower="-1.57" upper="1.57"/>
  </joint>

  <joint name="leg4_bar3_fix" type="fixed">
    <parent link="leg4_bar3"/>
    <child link="leg4_end"/>
    <origin xyz="0 0 -0.216284"/>
    <axis xyz="0 0 1" />
    <limit effort="300" velocity="2" lower="-1.57" upper="1.57"/>
  </joint>

  <!-- End effectors are assigned -->

  <link name="leg1_end">
    <visual>
      <geometry>
        <mesh filename="package://simulation/meshes/Foot.stl" scale="0.001 0.001 0.001"/>
      </geometry>
      <origin rpy="0 0 0" xyz="0 0 0"/>
      <material name="grey" />
    </visual>
    <collision>
      <origin rpy="0 0 0" xyz="0 0 0"/>
      <geometry>
        <cylinder length="0.0075" radius="0.005"/>
      </geometry>
      <surface>
        <friction>
          <ode>
            <mu>0.8</mu>
            <mu2>0.8</mu2>
          </ode>
        </friction>
      </surface>
    </collision>
    <inertial>
      <origin rpy="0 0 0" xyz="0 0 0"/>
      <mass value="0.004" />
      <inertia ixx="4.375e-8" ixy="0" ixz="0" iyy="4.375e-8" iyz="0" izz="5e-8" />
    </inertial>
  </link>
  <gazebo reference="leg1_end">
    <material>Gazebo/White</material>
  </gazebo>

  <link name="leg2_end">
    <visual>
      <geometry>
        <mesh filename="package://simulation/meshes/Foot.stl" scale="0.001 0.001 0.001"/>
      </geometry>
      <origin rpy="0 0 0" xyz="0 0 0"/>
      <material name="grey" />
    </visual>
    <collision>
      <origin rpy="0 0 0" xyz="0 0 0"/>
      <geometry>
        <cylinder length="0.0075" radius="0.005"/>
      </geometry>
      <surface>
        <friction>
          <ode>
            <mu>0.8</mu>
            <mu2>0.8</mu2>
          </ode>
        </friction>
      </surface>
    </collision>
    <inertial>
      <origin rpy="0 0 0" xyz="0 0 0"/>
      <mass value="0.004" />
      <inertia ixx="4.375e-8" ixy="0" ixz="0" iyy="4.375e-8" iyz="0" izz="5e-8" />
    </inertial>
  </link>
  <gazebo reference="leg2_end">
    <material>Gazebo/White</material>
  </gazebo>

  <link name="leg3_end">
    <visual>
      <geometry>
        <mesh filename="package://simulation/meshes/Foot.stl" scale="0.001 0.001 0.001"/>
      </geometry>
      <origin rpy="0 0 0" xyz="0 0 0"/>
      <material name="grey" />
    </visual>
    <collision>
      <origin rpy="0 0 0" xyz="0 0 0"/>
      <geometry>
        <cylinder length="0.0075" radius="0.005"/>
      </geometry>
      <surface>
        <friction>
          <ode>
            <mu>0.8</mu>
            <mu2>0.8</mu2>
          </ode>
        </friction>
      </surface>
    </collision>
    <inertial>
      <origin rpy="0 0 0" xyz="0 0 0"/>
      <mass value="0.004" />
      <inertia ixx="4.375e-8" ixy="0" ixz="0" iyy="4.375e-8" iyz="0" izz="5e-8" />
    </inertial>
  </link>
  <gazebo reference="leg3_end">
    <material>Gazebo/White</material>
  </gazebo>

  <link name="leg4_end">
    <visual>
      <geometry>
        <mesh filename="package://simulation/meshes/Foot.stl" scale="0.001 0.001 0.001"/>
      </geometry>
      <origin rpy="0 0 0" xyz="0 0 0"/>
      <material name="grey" />
    </visual>
    <collision>
      <origin rpy="0 0 0" xyz="0 0 0"/>
      <geometry>
        <cylinder length="0.0075" radius="0.005"/>
      </geometry>
      <surface>
        <friction>
          <ode>
            <mu>0.8</mu>
            <mu2>0.8</mu2>
          </ode>
        </friction>
      </surface>
    </collision>
    <inertial>
      <origin rpy="0 0 0" xyz="0 0 0"/>
      <mass value="0.004" />
      <inertia ixx="4.375e-8" ixy="0" ixz="0" iyy="4.375e-8" iyz="0" izz="5e-8" />
    </inertial>
  </link>
  <gazebo reference="leg4_end">
    <material>Gazebo/White</material>
  </gazebo>

  <joint name="hokuyo_joint" type="fixed">
    <axis xyz="0 1 0" />
    <origin xyz="0 0 0.288" rpy="0 0 0"/>
    <parent link="base"/>
    <child link="hokuyo"/>
  </joint>

  <!-- Hokuyo Laser -->
  <link name="hokuyo">
    <collision>
      <origin xyz="0 0 0" rpy="0 0 0"/>
      <geometry>
    <box size="0.06 0.06 0.06"/>
      </geometry>
    </collision>

    <visual>
      <origin xyz="0 0 0" rpy="0 0 0"/>
      <geometry>
        <mesh filename="package://simulation/meshes/hokuyo.dae"/>
      </geometry>
    </visual>

    <inertial>
      <mass value="1e-5" />
      <origin xyz="0 0 0" rpy="0 0 0"/>
      <inertia ixx="1e-6" ixy="0" ixz="0" iyy="1e-6" iyz="0" izz="1e-6" />
    </inertial>
  </link>


  <!-- hokuyo -->
  <gazebo reference="hokuyo">
    <sensor type="ray" name="head_hokuyo_sensor">
      <pose>0 0 0 0 0 0</pose>
      <visualize>false</visualize>
      <update_rate>10</update_rate>
      <ray>
        <scan>
          <horizontal>
            <samples>720</samples>
            <resolution>1</resolution>
            <min_angle>-1.5708</min_angle>
            <max_angle>1.5708</max_angle>
          </horizontal>
        </scan>
        <range>
          <min>0.10</min>
          <max>12.0</max>
          <resolution>0.01</resolution>
        </range>
        <noise>
          <type>gaussian</type>
          <!-- Noise parameters based on published spec for Hokuyo laser
               achieving "+-30mm" accuracy at range < 10m.  A mean of 0.0m and
               stddev of 0.01m will put 99.7% of samples within 0.03m of the true
               reading. -->
          <mean>0.0</mean>
          <stddev>0.01</stddev>
        </noise>
      </ray>
      <plugin name="gazebo_ros_head_hokuyo_controller" filename="libgazebo_ros_laser.so">
        <topicName>/scan</topicName>
        <frameName>hokuyo</frameName>
      </plugin>
    </sensor>
  </gazebo>


  <link name="camera_link">
    <collision>
      <origin xyz="0 0 0" rpy="0 0 0"/>
      <geometry>
        <box size="0.005 0.04 0.04"/>
      </geometry>
    </collision>

    <visual>
      <origin xyz="0 0 0" rpy="1.5708 0 1.5708"/>
      <geometry>
        <mesh filename="package://simulation/meshes/Camera.stl" scale="0.001 0.001 0.001"/>
      </geometry>
      <material name="green"/>
    </visual>

    <inertial>
      <mass value="0.01" />
      <origin xyz="0 0 0" rpy="0 0 0"/>
      <box_inertia m="0.01" x="0.005" y="0.04" z="0.04" />
      <inertia ixx="1e-6" ixy="0" ixz="0" iyy="1e-6" iyz="0" izz="1e-6" />
    </inertial>
  </link>
  <gazebo reference="camera_link">
    <material>Gazebo/Green</material>
  </gazebo>

  <joint name="camera_joint" type="fixed">
    <axis xyz="0 1 0" />
    <origin xyz=".08 0 0.228" rpy="0 0 0"/>
    <parent link="base"/>
    <child link="camera_link"/>
  </joint>

  <gazebo reference="camera_link">
    <sensor type="camera" name="camera1">
      <update_rate>30.0</update_rate>
      <camera name="head">
        <horizontal_fov>1.3962634</horizontal_fov>
        <image>
          <width>800</width>
          <height>800</height>
          <format>R8G8B8</format>
        </image>
        <clip>
          <near>0.02</near>
          <far>300</far>
        </clip>
        <noise>
          <type>gaussian</type>
          <!-- Noise is sampled independently per pixel on each frame.  
               That pixel's noise value is added to each of its color
               channels, which at that point lie in the range [0,1]. -->
          <mean>0.0</mean>
          <stddev>0.007</stddev>
        </noise>
      </camera>
      <plugin name="camera_controller" filename="libgazebo_ros_camera.so">
        <alwaysOn>true</alwaysOn>
        <updateRate>0.0</updateRate>
        <cameraName>charly/camera1</cameraName>
        <imageTopicName>image_raw</imageTopicName>
        <cameraInfoTopicName>camera_info</cameraInfoTopicName>
        <frameName>camera_link</frameName>
        <hackBaseline>0.07</hackBaseline>
        <distortionK1>0.0</distortionK1>
        <distortionK2>0.0</distortionK2>
        <distortionK3>0.0</distortionK3>
        <distortionT1>0.0</distortionT1>
        <distortionT2>0.0</distortionT2>
      </plugin>
    </sensor>
  </gazebo>


  <!-- Transmissions -->
  <transmission name="tran1">
    <type>transmission_interface/SimpleTransmission</type>
    <joint name="leg1_motor1">
      <hardwareInterface>hardware_interface/EffortJointInterface</hardwareInterface>
    </joint>
    <actuator name="leg1_servo1">
      <hardwareInterface>hardware_interface/EffortJointInterface</hardwareInterface>
      <mechanicalReduction>1</mechanicalReduction>
    </actuator>
  </transmission>

  <transmission name="tran2">
    <type>transmission_interface/SimpleTransmission</type>
    <joint name="leg1_motor2">
      <hardwareInterface>hardware_interface/EffortJointInterface</hardwareInterface>
    </joint>
    <actuator name="leg1_servo2">
      <hardwareInterface>hardware_interface/EffortJointInterface</hardwareInterface>
      <mechanicalReduction>1</mechanicalReduction>
    </actuator>
  </transmission>

  <transmission name="tran3">
    <type>transmission_interface/SimpleTransmission</type>
    <joint name="leg1_motor3">
      <hardwareInterface>hardware_interface/EffortJointInterface</hardwareInterface>
    </joint>
    <actuator name="leg1_servo3">
      <hardwareInterface>hardware_interface/EffortJointInterface</hardwareInterface>
      <mechanicalReduction>1</mechanicalReduction>
    </actuator>
  </transmission>

  <transmission name="tran4">
    <type>transmission_interface/SimpleTransmission</type>
    <joint name="leg2_motor1">
      <hardwareInterface>hardware_interface/EffortJointInterface</hardwareInterface>
    </joint>
    <actuator name="leg2_servo1">
      <hardwareInterface>hardware_interface/EffortJointInterface</hardwareInterface>
      <mechanicalReduction>1</mechanicalReduction>
    </actuator>
  </transmission>

  <transmission name="tran5">
    <type>transmission_interface/SimpleTransmission</type>
    <joint name="leg2_motor2">
      <hardwareInterface>hardware_interface/EffortJointInterface</hardwareInterface>
    </joint>
    <actuator name="leg2_servo2">
      <hardwareInterface>hardware_interface/EffortJointInterface</hardwareInterface>
      <mechanicalReduction>1</mechanicalReduction>
    </actuator>
  </transmission>

  <transmission name="tran6">
    <type>transmission_interface/SimpleTransmission</type>
    <joint name="leg2_motor3">
      <hardwareInterface>hardware_interface/EffortJointInterface</hardwareInterface>
    </joint>
    <actuator name="leg2_servo3">
      <hardwareInterface>hardware_interface/EffortJointInterface</hardwareInterface>
      <mechanicalReduction>1</mechanicalReduction>
    </actuator>
  </transmission>

  <transmission name="tran7">
    <type>transmission_interface/SimpleTransmission</type>
    <joint name="leg3_motor1">
      <hardwareInterface>hardware_interface/EffortJointInterface</hardwareInterface>
    </joint>
    <actuator name="leg3_servo1">
      <hardwareInterface>hardware_interface/EffortJointInterface</hardwareInterface>
      <mechanicalReduction>1</mechanicalReduction>
    </actuator>
  </transmission>

  <transmission name="tran8">
    <type>transmission_interface/SimpleTransmission</type>
    <joint name="leg3_motor2">
      <hardwareInterface>hardware_interface/EffortJointInterface</hardwareInterface>
    </joint>
    <actuator name="leg3_servo2">
      <hardwareInterface>hardware_interface/EffortJointInterface</hardwareInterface>
      <mechanicalReduction>1</mechanicalReduction>
    </actuator>
  </transmission>

  <transmission name="tran9">
    <type>transmission_interface/SimpleTransmission</type>
    <joint name="leg3_motor3">
      <hardwareInterface>hardware_interface/EffortJointInterface</hardwareInterface>
    </joint>
    <actuator name="leg3_servo3">
      <hardwareInterface>hardware_interface/EffortJointInterface</hardwareInterface>
      <mechanicalReduction>1</mechanicalReduction>
    </actuator>
  </transmission>

  <transmission name="tran10">
    <type>transmission_interface/SimpleTransmission</type>
    <joint name="leg4_motor1">
      <hardwareInterface>hardware_interface/EffortJointInterface</hardwareInterface>
    </joint>
    <actuator name="leg4_servo1">
      <hardwareInterface>hardware_interface/EffortJointInterface</hardwareInterface>
      <mechanicalReduction>1</mechanicalReduction>
    </actuator>
  </transmission>

  <transmission name="tran11">
    <type>transmission_interface/SimpleTransmission</type>
    <joint name="leg4_motor2">
      <hardwareInterface>hardware_interface/EffortJointInterface</hardwareInterface>
    </joint>
    <actuator name="leg4_servo2">
      <hardwareInterface>hardware_interface/EffortJointInterface</hardwareInterface>
      <mechanicalReduction>1</mechanicalReduction>
    </actuator>
  </transmission>

  <transmission name="tran12">
    <type>transmission_interface/SimpleTransmission</type>
    <joint name="leg4_motor3">
      <hardwareInterface>hardware_interface/EffortJointInterface</hardwareInterface>
    </joint>
    <actuator name="leg4_servo3">
      <hardwareInterface>hardware_interface/EffortJointInterface</hardwareInterface>
      <mechanicalReduction>1</mechanicalReduction>
    </actuator>
  </transmission>
  

   <!-- Plugin: ros_control -->
   <gazebo>
     <plugin name="gazebo_ros_control" filename="libgazebo_ros_control.so">
       <robotNamespace>/robot</robotNamespace>
       <legacyModeNS>true</legacyModeNS>
     </plugin>
   </gazebo>

</robot>
